Workbook

Sheet ESA01 - GHI1
B2: Mês/ano | C2: Quant de eventos > 1000 W/m² | D2: Qt. de eventos > 1367 W/m² | E2: Total de eventos | F2: Qt. eventos < 30 segundos | >1000 e <1367 W/m² | G2: Valor médio dos eventos < 30 segundos | >1000 e <1367 W/m² | H2: Valor máximo dos eventos < 30 segundos | >1000 e <1367 W/m² | I2: Qt. eventos 30<->60 segundos | >1000 e <1367 W/m² | J2: Valor médio dos eventos 30<->60 segundos | >1000 e <1367 W/m² | K2: Valor máximo dos eventos 30<->60 segundos | >1000 e <1367 W/m² | L2: Qt. eventos 60<->120 segundos | >1000 e <1367 W/m² | M2: Valor médio dos eventos 60<->120 segundos | >1000 e <1367 W/m² | N2: Valor máximo dos eventos 60<->120 segundos | >1000 e <1367 W/m² | O2: Qt. eventos < 120<->180 segundos | >1000 e <1367 W/m² | P2: Valor médio dos eventos < 120<->180 segundos | >1000 e <1367 W/m² | Q2: Valor máximo dos eventos < 120<->180 segundos | >1000 e <1367 W/m² | R2: Qt. eventos > 180 segundos | >1000 e <1367 W/m² | S2: Valor médio dos eventos > 180 segundos | >1000 e <1367 W/m² | T2: Valor máximo dos eventos > 180 segundos | >1000 e <1367 W/m² | U2: Qt. eventos < 30 segundos | >1367 W/m² | V2: Valor médio dos eventos < 30 segundos | >1367 W/m² | W2: Valor máximo dos eventos < 30 segundos | >1367 W/m² | X2: Qt. eventos 30<->60 segundos | >1367 W/m² | Y2: Valor médio dos eventos 30<->60 segundos | >1367 W/m² | Z2: Valor máximo dos eventos 30<->60 segundos | >1367 W/m² | AA2: Qt. eventos 60<->120 segundos | >1367 W/m² | AB2: Valor médio dos eventos 60<->120 segundos | >1367 W/m² | AC2: Valor máximo dos eventos 60<->120 segundos | >1367 W/m² | AD2: Qt. eventos < 120<->180 segundos | >1367 W/m² | AE2: Valor médio dos eventos < 120<->180 segundos | >1367 W/m² | AF2: Valor máximo dos eventos < 120<->180 segundos | >1367 W/m² | AG2: Qt. eventos > 180 segundos | >1367 W/m² | AH2: Valor médio dos eventos > 180 segundos | >1367 W/m² | AI2: Valor máximo dos eventos > 180 segundos | >1367 W/m² | AJ2: Qt. eventos < 30 segundos | Total | AK2: Qt. eventos 30<->60 segundos | Total | AL2: Qt. eventos 60<->120 segundos | Total | AM2: Qt. eventos < 120<->180 segundos | Total | AN2: Qt. eventos > 180 segundos | Total | AO2: Hora/Dia do maior evento | AP2: Valor do maior evento em W/m² | AQ2: Dia/Hora do Evento de maior duração >1000 e <1367 W/m² | AR2: Duração do Evento >1000 e <1367 W/m² | AS2: Valor médio do evento de maior duração >1000 e < 1367 W/m² | AT2: Valor máximo do evento de maior duração >1000 e < 1367 W/m² | AU2: Dia/Hora do Evento de maior duração >1367 W/m² | AV2: Duração Evento >1367 W/m² | AW2: Valor médio do evento de maior duração >1000 e < 1367 W/m² | AX2: Valor máximo do evento de maior duração >1000 e < 1367 W/m²
B3: 44501 | C3: 46 | D3: 2 | E3: 48 | F3: 42 | G3: 1162.978 | H3: 1366 | I3: 4 | J3: 1127.6971 | K3: 1195 | U3: 2 | V3: 1372.0417 | W3: 1378 | AJ3: 44 | AK3: 4 | AO3: 44515.474 | AP3: 1378 | AQ3: 44516.39 | AR3: 60 | AS3: 1174.6167 | AT3: 1195 | AU3: 44515.474 | AV3: 9 | AW3: 1374.3333 | AX3: 1378
B4: 44531 | C4: 202 | D4: 61 | E4: 263 | F4: 179 | G4: 1273.5892 | H4: 1366 | I4: 15 | J4: 1247.5368 | K4: 1366 | L4: 5 | M4: 1274.1532 | N4: 1341 | O4: 3 | P4: 1338.5639 | Q4: 1365 | U4: 56 | V4: 1403.0636 | W4: 1620 | X4: 4 | Y4: 1387.1565 | Z4: 1453 | AG4: 1 | AH4: 1376.6495 | AI4: 1386 | AJ4: 235 | AK4: 19 | AL4: 5 | AM4: 3 | AN4: 1 | AO4: 44544.454 | AP4: 1620 | AQ4: 44561.523 | AR4: 177 | AS4: 1345.209 | AT4: 1365 | AU4: 44561.52 | AV4: 194 | AW4: 1376.6495 | AX4: 1386
B5: 44562 | C5: 173 | D5: 114 | E5: 287 | F5: 159 | G5: 1279.9883 | H5: 1366 | I5: 7 | J5: 1209.3761 | K5: 1364 | L5: 6 | M5: 1183.9667 | N5: 1343 | O5: 1 | P5: 1315.3281 | Q5: 1340 | U5: 90 | V5: 1398.3631 | W5: 1602 | X5: 17 | Y5: 1415.446 | Z5: 1607 | AA5: 4 | AB5: 1459.4585 | AC5: 1567 | AD5: 3 | AE5: 1405.706 | AF5: 1468 | AJ5: 249 | AK5: 24 | AL5: 10 | AM5: 4 | AO5: 44576.488 | AP5: 1607 | AQ5: 44567.535 | AR5: 128 | AS5: 1315.3281 | AT5: 1340 | AU5: 44562.503 | AV5: 162 | AW5: 1438.9444 | AX5: 1468
B6: 44593 | C6: 91 | D6: 75 | E6: 166 | F6: 78 | G6: 1248.6187 | H6: 1366 | I6: 7 | J6: 1081.5292 | K6: 1366 | L6: 4 | M6: 1195.2145 | N6: 1366 | O6: 2 | P6: 1133.9466 | Q6: 1253 | U6: 61 | V6: 1417.8607 | W6: 1593 | X6: 6 | Y6: 1407.3703 | Z6: 1463 | AA6: 4 | AB6: 1404.6307 | AC6: 1448 | AD6: 4 | AE6: 1408.002 | AF6: 1509 | AJ6: 139 | AK6: 13 | AL6: 8 | AM6: 6 | AO6: 44598.498 | AP6: 1593 | AQ6: 44604.56 | AR6: 176 | AS6: 1244.0057 | AT6: 1253 | AU6: 44614.52 | AV6: 146 | AW6: 1389.9041 | AX6: 1416
B7: 44621 | C7: 298 | D7: 168 | E7: 466 | F7: 274 | G7: 1269.3215 | H7: 1366 | I7: 16 | J7: 1206.305 | K7: 1366 | L7: 5 | M7: 1245.2076 | N7: 1327 | O7: 2 | P7: 1234.4914 | Q7: 1337 | R7: 1 | S7: 1119.0309 | T7: 1153 | U7: 151 | V7: 1401.1144 | W7: 1562 | X7: 9 | Y7: 1423.6836 | Z7: 1569 | AA7: 8 | AB7: 1421.0195 | AC7: 1544 | AJ7: 425 | AK7: 25 | AL7: 13 | AM7: 2 | AN7: 1 | AO7: 44645.455 | AP7: 1569 | AQ7: 44633.59 | AR7: 259 | AS7: 1119.0309 | AT7: 1153 | AU7: 44633.503 | AV7: 96 | AW7: 1458.4167 | AX7: 1544
B8: 44652 | C8: 517 | D8: 94 | E8: 611 | F8: 476 | G8: 1220.1934 | H8: 1366 | I8: 33 | J8: 1253.5788 | K8: 1366 | L8: 7 | M8: 1263.4933 | N8: 1355 | R8: 1 | S8: 1153.0521 | T8: 1177 | U8: 83 | V8: 1399.3757 | W8: 1509 | X8: 9 | Y8: 1430.6602 | Z8: 1512 | AD8: 1 | AE8: 1464.291 | AF8: 1493 | AG8: 1 | AH8: 1443.3602 | AI8: 1504 | AJ8: 559 | AK8: 42 | AL8: 7 | AM8: 1 | AN8: 2 | AO8: 44663.484 | AP8: 1512 | AQ8: 44667.404 | AR8: 326 | AS8: 1153.0521 | AT8: 1177 | AU8: 44652.516 | AV8: 261 | AW8: 1443.3602 | AX8: 1504
B9: 44682 | C9: 464 | D9: 2 | E9: 466 | F9: 417 | G9: 1176.6307 | H9: 1364 | I9: 34 | J9: 1190.2186 | K9: 1356 | L9: 9 | M9: 1196.4461 | N9: 1306 | O9: 2 | P9: 1212.1245 | Q9: 1261 | R9: 2 | S9: 1228.6492 | T9: 1265 | U9: 2 | V9: 1373.6364 | W9: 1378 | AJ9: 419 | AK9: 34 | AL9: 9 | AM9: 2 | AN9: 2 | AO9: 44708.495 | AP9: 1378 | AQ9: 44687.426 | AR9: 234 | AS9: 1228.3504 | AT9: 1251 | AU9: 44708.495 | AV9: 10 | AW9: 1373.3 | AX9: 1378
B10: 44713 | C10: 516 | D10: 1 | E10: 517 | F10: 465 | G10: 1134.5926 | H10: 1353 | I10: 35 | J10: 1138.7556 | K10: 1338 | L10: 13 | M10: 1185.2165 | N10: 1333 | O10: 3 | P10: 1178.2077 | Q10: 1280 | U10: 1 | V10: 1385.6667 | W10: 1390 | AJ10: 466 | AK10: 35 | AL10: 13 | AM10: 3 | AO10: 44718.499 | AP10: 1390 | AQ10: 44723.467 | AR10: 147 | AS10: 1230.3878 | AT10: 1280 | AU10: 44718.499 | AV10: 3 | AW10: 1385.6667 | AX10: 1390
B11: 44743 | C11: 463 | D11: 5 | E11: 468 | F11: 410 | G11: 1143.7239 | H11: 1366 | I11: 37 | J11: 1154.6696 | K11: 1346 | L11: 12 | M11: 1177.2748 | N11: 1289 | O11: 4 | P11: 1127.7222 | Q11: 1239 | U11: 5 | V11: 1409.1241 | W11: 1500 | AJ11: 415 | AK11: 37 | AL11: 12 | AM11: 4 | AO11: 44757.51 | AP11: 1500 | AQ11: 44769.46 | AR11: 160 | AS11: 1212.1063 | AT11: 1228 | AU11: 44757.51 | AV11: 14 | AW11: 1462.2143 | AX11: 1500
B12: 44774 | C12: 688 | D12: 80 | E12: 768 | F12: 627 | G12: 1206.7525 | H12: 1366 | I12: 43 | J12: 1222.6456 | K12: 1366 | L12: 13 | M12: 1230.6699 | N12: 1366 | O12: 5 | P12: 1245.4377 | Q12: 1357 | U12: 73 | V12: 1400.5843 | W12: 1483 | X12: 7 | Y12: 1400.364 | Z12: 1462 | AJ12: 700 | AK12: 50 | AL12: 13 | AM12: 5 | AO12: 44804.479 | AP12: 1483 | AQ12: 44774.461 | AR12: 153 | AS12: 1217.5556 | AT12: 1258 | AU12: 44804.487 | AV12: 52 | AW12: 1385.6923 | AX12: 1393
B13: 44805 | C13: 419 | D13: 74 | E13: 493 | F13: 367 | G13: 1205.9323 | H13: 1366 | I13: 34 | J13: 1214.6988 | K13: 1366 | L13: 15 | M13: 1208.3183 | N13: 1366 | O13: 3 | P13: 1255.4616 | Q13: 1365 | U13: 68 | V13: 1392.9921 | W13: 1533 | X13: 5 | Y13: 1441.0033 | Z13: 1487 | AA13: 1 | AB13: 1495.2286 | AC13: 1521 | AJ13: 435 | AK13: 39 | AL13: 16 | AM13: 3 | AO13: 44826.441 | AP13: 1533 | AQ13: 44808.523 | AR13: 156 | AS13: 1343.3846 | AT13: 1365 | AU13: 44817.485 | AV13: 70 | AW13: 1495.2286 | AX13: 1521
B14: 44835 | C14: 124 | D14: 58 | E14: 182 | F14: 117 | G14: 1282.5316 | H14: 1366 | I14: 6 | J14: 1278.0295 | K14: 1365 | L14: 1 | M14: 1048.8 | N14: 1054 | U14: 46 | V14: 1390.3302 | W14: 1489 | X14: 11 | Y14: 1409.181 | Z14: 1515 | AA14: 1 | AB14: 1410.5 | AC14: 1430 | AJ14: 163 | AK14: 17 | AL14: 2 | AO14: 44858.459 | AP14: 1515 | AQ14: 44853.367 | AR14: 85 | AS14: 1048.8 | AT14: 1054 | AU14: 44858.468 | AV14: 76 | AW14: 1410.5 | AX14: 1430
B15: 44866 | C15: 227 | D15: 110 | E15: 337 | F15: 182 | G15: 1234.5673 | H15: 1366 | I15: 24 | J15: 1183.3972 | K15: 1366 | L15: 16 | M15: 1152.2015 | N15: 1322 | O15: 4 | P15: 1260.4416 | Q15: 1366 | R15: 1 | S15: 1270.6721 | T15: 1290 | U15: 95 | V15: 1419.8754 | W15: 1654 | X15: 7 | Y15: 1428.2688 | Z15: 1582 | AA15: 8 | AB15: 1421.0593 | AC15: 1527 | AJ15: 277 | AK15: 31 | AL15: 24 | AM15: 4 | AN15: 1 | AO15: 44870.503 | AP15: 1654 | AQ15: 44874.401 | AR15: 498 | AS15: 1198.5241 | AT15: 1236 | AU15: 44871.514 | AV15: 108 | AW15: 1505.1204 | AX15: 1527
B16: 44896 | C16: 226 | D16: 62 | E16: 288 | F16: 208 | G16: 1230.2857 | H16: 1366 | I16: 7 | J16: 1214.1474 | K16: 1366 | L16: 8 | M16: 1271.477 | N16: 1366 | O16: 3 | P16: 1140.6984 | Q16: 1260 | U16: 51 | V16: 1400.2122 | W16: 1575 | X16: 4 | Y16: 1408.5156 | Z16: 1466 | AA16: 3 | AB16: 1396.4759 | AC16: 1454 | AD16: 4 | AE16: 1394.4478 | AF16: 1432 | AJ16: 259 | AK16: 11 | AL16: 11 | AM16: 7 | AO16: 44900.486 | AP16: 1575 | AQ16: 44920.362 | AR16: 155 | AS16: 1052.7097 | AT16: 1079 | AU16: 44916.469 | AV16: 169 | AW16: 1403.4675 | AX16: 1432
B17: 44927 | C17: 69 | D17: 17 | E17: 86 | F17: 64 | G17: 1235.5833 | H17: 1366 | I17: 4 | J17: 1255.9263 | K17: 1366 | L17: 1 | M17: 1309.8224 | N17: 1326 | U17: 16 | V17: 1380.4025 | W17: 1408 | AA17: 1 | AB17: 1385.7742 | AC17: 1394 | AJ17: 80 | AK17: 4 | AL17: 2 | AO17: 44954.449 | AP17: 1408 | AQ17: 44949.425 | AR17: 107 | AS17: 1309.8224 | AT17: 1326 | AU17: 44943.47 | AV17: 62 | AW17: 1385.7742 | AX17: 1394
B18: 44958 | C18: 110 | D18: 101 | E18: 211 | F18: 100 | G18: 1267.6096 | H18: 1366 | I18: 5 | J18: 1224.7294 | K18: 1341 | L18: 3 | M18: 1288.277 | N18: 1349 | R18: 2 | S18: 1193.4704 | T18: 1272 | U18: 92 | V18: 1407.8313 | W18: 1558 | X18: 7 | Y18: 1417.8311 | Z18: 1487 | AA18: 1 | AB18: 1412.9474 | AC18: 1426 | AD18: 1 | AE18: 1440.3972 | AF18: 1502 | AJ18: 192 | AK18: 12 | AL18: 4 | AM18: 1 | AN18: 2 | AO18: 44979.519 | AP18: 1558 | AQ18: 44965.583 | AR18: 120 | AS18: 1203.831 | AT18: 1272 | AU18: 44979.499 | AV18: 141 | AW18: 1440.3972 | AX18: 1502
B19: 44986 | C19: 257 | D19: 82 | E19: 339 | F19: 236 | G19: 1268.9518 | H19: 1366 | I19: 12 | J19: 1209.5604 | K19: 1366 | L19: 8 | M19: 1255.0614 | N19: 1366 | R19: 1 | S19: 1175.2359 | T19: 1262 | U19: 64 | V19: 1409.5124 | W19: 1552 | X19: 12 | Y19: 1409.0705 | Z19: 1566 | AA19: 5 | AB19: 1439.442 | AC19: 1526 | AD19: 1 | AE19: 1388.4029 | AF19: 1403 | AJ19: 300 | AK19: 24 | AL19: 13 | AM19: 1 | AN19: 1 | AO19: 45010.505 | AP19: 1566 | AQ19: 45004.38 | AR19: 195 | AS19: 1175.2359 | AT19: 1262 | AU19: 45004.446 | AV19: 139 | AW19: 1388.4029 | AX19: 1403
B25: Mês/ano | C25: Ocorrências | E25: Mês/ano | F25: 1000 ≥ Ig < 1300 W/m² | G25: Ig > 1367 W/m² | I25: Mês/ano | J25: < 30 seg | K25: < 1 min | L25: < 2 minutos | M25: < 3 minutos | N25: ≥ 3 minutos | P25: =I25 -> Mês/ano | Q25: < 30 seg | R25: < 1 min | S25: < 2 minutos | T25: < 3 minutos | U25: ≥ 3 minutos | W25: =P25 -> Mês/ano | X25: < 30 seg | Y25: < 1 min | Z25: < 2 minutos | AA25: < 3 minutos | AB25: ≥ 3 minutos | AD25: Dia/mês | AE25: Evento de maior magnitude [W/m²] | AF25: ="" | AG25: Dia/mês | AH25: Maior duração >1000 e <1367 [W/m²] | AI25: Maior duração >1367 [W/m²] | AJ25: ="" | AL25: Mês/ano | AM25: < 30 seg | AN25: < 1 min | AO25: < 2 minutos | AP25: < 3 minutos | AQ25: ≥ 3 minutos
B26: =B3 -> 44501 | C26: =E3 -> 48 | E26: =B26 -> 44501 | F26: =C3/E3 -> 0.95833333 | G26: =D3/E3 -> 0.041666667 | I26: =E26 -> 44501 | J26: =AJ3/$E3 -> 0.91666667 | K26: =AK3/$E3 -> 0.083333333 | L26: =AL3/$E3 -> 0 | M26: =AM3/$E3 -> 0 | N26: =AN3/$E3 -> 0 | P26: =I26 -> 44501 | Q26: =G3 -> 1162.978 | R26: =J3 -> 1127.6971 | S26: =M3 | T26: =P3 | U26: =S3 | W26: =P26 -> 44501 | X26: =V3 -> 1372.0417 | Y26: =Y3 | Z26: =AB3 | AA26: =AE3 | AB26: =AH3 | AD26: =W26 -> 44501 | AE26: =AP3 -> 1378 | AG26: =W26 -> 44501 | AH26: =AR3 -> 60 | AI26: =AV3 -> 9 | AL26: =AG26 -> 44501 | AM26: =AJ3/$E3 -> 0.91666667 | AN26: =AK3/$E3 -> 0.083333333 | AO26: =AL3/$E3 -> 0 | AP26: =AM3/$E3 -> 0 | AQ26: =AN3/$E3 -> 0
B27: =B4 -> 44531 | C27: =E4 -> 263 | E27: =B27 -> 44531 | F27: =C4/E4 -> 0.76806084 | G27: =D4/E4 -> 0.23193916 | I27: =E27 -> 44531 | J27: =AJ4/$E4 -> 0.89353612 | K27: =AK4/$E4 -> 0.072243346 | L27: =AL4/$E4 -> 0.019011407 | M27: =AM4/$E4 -> 0.011406844 | N27: =AN4/$E4 -> 0.0038022814 | P27: =I27 -> 44531 | Q27: =G4 -> 1273.5892 | R27: =J4 -> 1247.5368 | S27: =M4 -> 1274.1532 | T27: =P4 -> 1338.5639 | U27: =S4 | W27: =P27 -> 44531 | X27: =V4 -> 1403.0636 | Y27: =Y4 -> 1387.1565 | Z27: =AB4 | AA27: =AE4 | AB27: =AH4 -> 1376.6495 | AD27: =AO4 -> 44544.454 | AE27: =AP4 -> 1620 | AG27: =W27 -> 44531 | AH27: =AR4 -> 177 | AI27: =AV4 -> 194 | AL27: =AG27 -> 44531 | AM27: =AJ4/$E4 -> 0.89353612 | AN27: =AK4/$E4 -> 0.072243346 | AO27: =AL4/$E4 -> 0.019011407 | AP27: =AM4/$E4 -> 0.011406844 | AQ27: =AN4/$E4 -> 0.0038022814
B28: =B5 -> 44562 | C28: =E5 -> 287 | E28: =B28 -> 44562 | F28: =C5/E5 -> 0.60278746 | G28: =D5/E5 -> 0.39721254 | I28: =E28 -> 44562 | J28: =AJ5/$E5 -> 0.86759582 | K28: =AK5/$E5 -> 0.083623693 | L28: =AL5/$E5 -> 0.034843206 | M28: =AM5/$E5 -> 0.013937282 | N28: =AN5/$E5 -> 0 | P28: =I28 -> 44562 | Q28: =G5 -> 1279.9883 | R28: =J5 -> 1209.3761 | S28: =M5 -> 1183.9667 | T28: =P5 -> 1315.3281 | U28: =S5 | W28: =P28 -> 44562 | X28: =V5 -> 1398.3631 | Y28: =Y5 -> 1415.446 | Z28: =AB5 -> 1459.4585 | AA28: =AE5 -> 1405.706 | AB28: =AH5 | AD28: =AO5 -> 44576.488 | AE28: =AP5 -> 1607 | AG28: =W28 -> 44562 | AH28: =AR5 -> 128 | AI28: =AV5 -> 162 | AL28: =AG28 -> 44562 | AM28: =AJ5/$E5 -> 0.86759582 | AN28: =AK5/$E5 -> 0.083623693 | AO28: =AL5/$E5 -> 0.034843206 | AP28: =AM5/$E5 -> 0.013937282 | AQ28: =AN5/$E5 -> 0
B29: =B6 -> 44593 | C29: =E6 -> 166 | E29: =B29 -> 44593 | F29: =C6/E6 -> 0.54819277 | G29: =D6/E6 -> 0.45180723 | I29: =E29 -> 44593 | J29: =AJ6/$E6 -> 0.8373494 | K29: =AK6/$E6 -> 0.078313253 | L29: =AL6/$E6 -> 0.048192771 | M29: =AM6/$E6 -> 0.036144578 | N29: =AN6/$E6 -> 0 | P29: =I29 -> 44593 | Q29: =G6 -> 1248.6187 | R29: =J6 -> 1081.5292 | S29: =M6 -> 1195.2145 | T29: =P6 -> 1133.9466 | U29: =S6 | W29: =P29 -> 44593 | X29: =V6 -> 1417.8607 | Y29: =Y6 -> 1407.3703 | Z29: =AB6 -> 1404.6307 | AA29: =AE6 -> 1408.002 | AB29: =AH6 | AD29: =AO6 -> 44598.498 | AE29: =AP6 -> 1593 | AG29: =W29 -> 44593 | AH29: =AR6 -> 176 | AI29: =AV6 -> 146 | AL29: =AG29 -> 44593 | AM29: =AJ6/$E6 -> 0.8373494 | AN29: =AK6/$E6 -> 0.078313253 | AO29: =AL6/$E6 -> 0.048192771 | AP29: =AM6/$E6 -> 0.036144578 | AQ29: =AN6/$E6 -> 0
B30: =B7 -> 44621 | C30: =E7 -> 466 | E30: =B30 -> 44621 | F30: =C7/E7 -> 0.63948498 | G30: =D7/E7 -> 0.36051502 | I30: =E30 -> 44621 | J30: =AJ7/$E7 -> 0.91201717 | K30: =AK7/$E7 -> 0.053648069 | L30: =AL7/$E7 -> 0.027896996 | M30: =AM7/$E7 -> 0.0042918455 | N30: =AN7/$E7 -> 0.0021459227 | P30: =I30 -> 44621 | Q30: =G7 -> 1269.3215 | R30: =J7 -> 1206.305 | S30: =M7 -> 1245.2076 | T30: =P7 -> 1234.4914 | U30: =S7 -> 1119.0309 | W30: =P30 -> 44621 | X30: =V7 -> 1401.1144 | Y30: =Y7 -> 1423.6836 | Z30: =AB7 -> 1421.0195 | AA30: =AE7 | AB30: =AH7 | AD30: =AO7 -> 44645.455 | AE30: =AP7 -> 1569 | AG30: =W30 -> 44621 | AH30: =AR7 -> 259 | AI30: =AV7 -> 96 | AL30: =AG30 -> 44621 | AM30: =AJ7/$E7 -> 0.91201717 | AN30: =AK7/$E7 -> 0.053648069 | AO30: =AL7/$E7 -> 0.027896996 | AP30: =AM7/$E7 -> 0.0042918455 | AQ30: =AN7/$E7 -> 0.0021459227
B31: =B8 -> 44652 | C31: =E8 -> 611 | E31: =B31 -> 44652 | F31: =C8/E8 -> 0.84615385 | G31: =D8/E8 -> 0.15384615 | I31: =E31 -> 44652 | J31: =AJ8/$E8 -> 0.91489362 | K31: =AK8/$E8 -> 0.068739771 | L31: =AL8/$E8 -> 0.011456628 | M31: =AM8/$E8 -> 0.0016366612 | N31: =AN8/$E8 -> 0.0032733224 | P31: =I31 -> 44652 | Q31: =G8 -> 1220.1934 | R31: =J8 -> 1253.5788 | S31: =M8 -> 1263.4933 | T31: =P8 | U31: =S8 -> 1153.0521 | W31: =P31 -> 44652 | X31: =V8 -> 1399.3757 | Y31: =Y8 -> 1430.6602 | Z31: =AB8 | AA31: =AE8 -> 1464.291 | AB31: =AH8 -> 1443.3602 | AD31: =AO8 -> 44663.484 | AE31: =AP8 -> 1512 | AG31: =W31 -> 44652 | AH31: =AR8 -> 326 | AI31: =AV8 -> 261 | AL31: =AG31 -> 44652 | AM31: =AJ8/$E8 -> 0.91489362 | AN31: =AK8/$E8 -> 0.068739771 | AO31: =AL8/$E8 -> 0.011456628 | AP31: =AM8/$E8 -> 0.0016366612 | AQ31: =AN8/$E8 -> 0.0032733224
B32: =B9 -> 44682 | C32: =E9 -> 466 | E32: =B32 -> 44682 | F32: =C9/E9 -> 0.99570815 | G32: =D9/E9 -> 0.0042918455 | I32: =E32 -> 44682 | J32: =AJ9/$E9 -> 0.89914163 | K32: =AK9/$E9 -> 0.072961373 | L32: =AL9/$E9 -> 0.019313305 | M32: =AM9/$E9 -> 0.0042918455 | N32: =AN9/$E9 -> 0.0042918455 | P32: =I32 -> 44682 | Q32: =G9 -> 1176.6307 | R32: =J9 -> 1190.2186 | S32: =M9 -> 1196.4461 | T32: =P9 -> 1212.1245 | U32: =S9 -> 1228.6492 | W32: =P32 -> 44682 | X32: =V9 -> 1373.6364 | Y32: =Y9 | Z32: =AB9 | AA32: =AE9 | AB32: =AH9 | AD32: =AO9 -> 44708.495 | AE32: =AP9 -> 1378 | AG32: =W32 -> 44682 | AH32: =AR9 -> 234 | AI32: =AV9 -> 10 | AL32: =AG32 -> 44682 | AM32: =AJ9/$E9 -> 0.89914163 | AN32: =AK9/$E9 -> 0.072961373 | AO32: =AL9/$E9 -> 0.019313305 | AP32: =AM9/$E9 -> 0.0042918455 | AQ32: =AN9/$E9 -> 0.0042918455
B33: =B10 -> 44713 | C33: =E10 -> 517 | E33: =B33 -> 44713 | F33: =C10/E10 -> 0.99806576 | G33: =D10/E10 -> 0.001934236 | I33: =E33 -> 44713 | J33: =AJ10/$E10 -> 0.90135397 | K33: =AK10/$E10 -> 0.067698259 | L33: =AL10/$E10 -> 0.025145068 | M33: =AM10/$E10 -> 0.0058027079 | N33: =AN10/$E10 -> 0 | P33: =I33 -> 44713 | Q33: =G10 -> 1134.5926 | R33: =J10 -> 1138.7556 | S33: =M10 -> 1185.2165 | T33: =P10 -> 1178.2077 | U33: =S10 | W33: =P33 -> 44713 | X33: =V10 -> 1385.6667 | Y33: =Y10 | Z33: =AB10 | AA33: =AE10 | AB33: =AH10 | AD33: =AO10 -> 44718.499 | AE33: =AP10 -> 1390 | AG33: =W33 -> 44713 | AH33: =AR10 -> 147 | AI33: =AV10 -> 3 | AL33: =AG33 -> 44713 | AM33: =AJ10/$E10 -> 0.90135397 | AN33: =AK10/$E10 -> 0.067698259 | AO33: =AL10/$E10 -> 0.025145068 | AP33: =AM10/$E10 -> 0.0058027079 | AQ33: =AN10/$E10 -> 0
B34: =B11 -> 44743 | C34: =E11 -> 468 | E34: =B34 -> 44743 | F34: =C11/E11 -> 0.98931624 | G34: =D11/E11 -> 0.010683761 | I34: =E34 -> 44743 | J34: =AJ11/$E11 -> 0.88675214 | K34: =AK11/$E11 -> 0.079059829 | L34: =AL11/$E11 -> 0.025641026 | M34: =AM11/$E11 -> 0.0085470085 | N34: =AN11/$E11 -> 0 | P34: =I34 -> 44743 | Q34: =G11 -> 1143.7239 | R34: =J11 -> 1154.6696 | S34: =M11 -> 1177.2748 | T34: =P11 -> 1127.7222 | U34: =S11 | W34: =P34 -> 44743 | X34: =V11 -> 1409.1241 | Y34: =Y11 | Z34: =AB11 | AA34: =AE11 | AB34: =AH11 | AD34: =AO11 -> 44757.51 | AE34: =AP11 -> 1500 | AG34: =W34 -> 44743 | AH34: =AR11 -> 160 | AI34: =AV11 -> 14 | AL34: =AG34 -> 44743 | AM34: =AJ11/$E11 -> 0.88675214 | AN34: =AK11/$E11 -> 0.079059829 | AO34: =AL11/$E11 -> 0.025641026 | AP34: =AM11/$E11 -> 0.0085470085 | AQ34: =AN11/$E11 -> 0
B35: =B12 -> 44774 | C35: =E12 -> 768 | E35: =B35 -> 44774 | F35: =C12/E12 -> 0.89583333 | G35: =D12/E12 -> 0.10416667 | I35: =E35 -> 44774 | J35: =AJ12/$E12 -> 0.91145833 | K35: =AK12/$E12 -> 0.065104167 | L35: =AL12/$E12 -> 0.016927083 | M35: =AM12/$E12 -> 0.0065104167 | N35: =AN12/$E12 -> 0 | P35: =I35 -> 44774 | Q35: =G12 -> 1206.7525 | R35: =J12 -> 1222.6456 | S35: =M12 -> 1230.6699 | T35: =P12 -> 1245.4377 | U35: =S12 | W35: =P35 -> 44774 | X35: =V12 -> 1400.5843 | Y35: =Y12 -> 1400.364 | Z35: =AB12 | AA35: =AE12 | AB35: =AH12 | AD35: =AO12 -> 44804.479 | AE35: =AP12 -> 1483 | AG35: =W35 -> 44774 | AH35: =AR12 -> 153 | AI35: =AV12 -> 52 | AL35: =AG35 -> 44774 | AM35: =AJ12/$E12 -> 0.91145833 | AN35: =AK12/$E12 -> 0.065104167 | AO35: =AL12/$E12 -> 0.016927083 | AP35: =AM12/$E12 -> 0.0065104167 | AQ35: =AN12/$E12 -> 0
B36: =B13 -> 44805 | C36: =E13 -> 493 | E36: =B36 -> 44805 | F36: =C13/E13 -> 0.84989858 | G36: =D13/E13 -> 0.15010142 | I36: =E36 -> 44805 | J36: =AJ13/$E13 -> 0.88235294 | K36: =AK13/$E13 -> 0.079107505 | L36: =AL13/$E13 -> 0.032454361 | M36: =AM13/$E13 -> 0.0060851927 | N36: =AN13/$E13 -> 0 | P36: =I36 -> 44805 | Q36: =G13 -> 1205.9323 | R36: =J13 -> 1214.6988 | S36: =M13 -> 1208.3183 | T36: =P13 -> 1255.4616 | U36: =S13 | W36: =P36 -> 44805 | X36: =V13 -> 1392.9921 | Y36: =Y13 -> 1441.0033 | Z36: =AB13 -> 1495.2286 | AA36: =AE13 | AB36: =AH13 | AD36: =AO13 -> 44826.441 | AE36: =AP13 -> 1533 | AG36: =W36 -> 44805 | AH36: =AR13 -> 156 | AI36: =AV13 -> 70 | AL36: =AG36 -> 44805 | AM36: =AJ13/$E13 -> 0.88235294 | AN36: =AK13/$E13 -> 0.079107505 | AO36: =AL13/$E13 -> 0.032454361 | AP36: =AM13/$E13 -> 0.0060851927 | AQ36: =AN13/$E13 -> 0
B37: =B14 -> 44835 | C37: =E14 -> 182 | E37: =B37 -> 44835 | F37: =C14/E14 -> 0.68131868 | G37: =D14/E14 -> 0.31868132 | I37: =E37 -> 44835 | J37: =AJ14/$E14 -> 0.8956044 | K37: =AK14/$E14 -> 0.093406593 | L37: =AL14/$E14 -> 0.010989011 | M37: =AM14/$E14 -> 0 | N37: =AN14/$E14 -> 0 | P37: =I37 -> 44835 | Q37: =G14 -> 1282.5316 | R37: =J14 -> 1278.0295 | S37: =M14 -> 1048.8 | T37: =P14 | U37: =S14 | W37: =P37 -> 44835 | X37: =V14 -> 1390.3302 | Y37: =Y14 -> 1409.181 | Z37: =AB14 -> 1410.5 | AA37: =AE14 | AB37: =AH14 | AD37: =AO14 -> 44858.459 | AE37: =AP14 -> 1515 | AG37: =W37 -> 44835 | AH37: =AR14 -> 85 | AI37: =AV14 -> 76 | AL37: =AG37 -> 44835 | AM37: =AJ14/$E14 -> 0.8956044 | AN37: =AK14/$E14 -> 0.093406593 | AO37: =AL14/$E14 -> 0.010989011 | AP37: =AM14/$E14 -> 0 | AQ37: =AN14/$E14 -> 0
B38: =B15 -> 44866 | C38: =E15 -> 337 | E38: =B38 -> 44866 | F38: =C15/E15 -> 0.6735905 | G38: =D15/E15 -> 0.3264095 | I38: =E38 -> 44866 | J38: =AJ15/$E15 -> 0.82195846 | K38: =AK15/$E15 -> 0.091988131 | L38: =AL15/$E15 -> 0.071216617 | M38: =AM15/$E15 -> 0.011869436 | N38: =AN15/$E15 -> 0.002967359 | P38: =I38 -> 44866 | Q38: =G15 -> 1234.5673 | R38: =J15 -> 1183.3972 | S38: =M15 -> 1152.2015 | T38: =P15 -> 1260.4416 | U38: =S15 -> 1270.6721 | W38: =P38 -> 44866 | X38: =V15 -> 1419.8754 | Y38: =Y15 -> 1428.2688 | Z38: =AB15 -> 1421.0593 | AA38: =AE15 | AB38: =AH15 | AD38: =AO15 -> 44870.503 | AE38: =AP15 -> 1654 | AG38: =W38 -> 44866 | AH38: =AR15 -> 498 | AI38: =AV15 -> 108 | AL38: =AG38 -> 44866 | AM38: =AJ15/$E15 -> 0.82195846 | AN38: =AK15/$E15 -> 0.091988131 | AO38: =AL15/$E15 -> 0.071216617 | AP38: =AM15/$E15 -> 0.011869436 | AQ38: =AN15/$E15 -> 0.002967359
... B42: =B19 -> 44986 | C42: =E19 -> 339 | E42: =B42 -> 44986 | F42: =C19/E19 -> 0.75811209 | G42: =D19/E19 -> 0.24188791 | I42: =E42 -> 44986 | J42: =AJ19/$E19 -> 0.88495575 | K42: =AK19/$E19 -> 0.07079646 | L42: =AL19/$E19 -> 0.038348083 | M42: =AM19/$E19 -> 0.0029498525 | N42: =AN19/$E19 -> 0.0029498525 | P42: =I42 -> 44986 | Q42: =G19 -> 1268.9518 | R42: =J19 -> 1209.5604 | S42: =M19 -> 1255.0614 | T42: =P19 | U42: =S19 -> 1175.2359 | W42: =P42 -> 44986 | X42: =V19 -> 1409.5124 | Y42: =Y19 -> 1409.0705 | Z42: =AB19 -> 1439.442 | AA42: =AE19 -> 1388.4029 | AB42: =AH19 | AD42: =AO19 -> 45010.505 | AE42: =AP19 -> 1566 | AG42: =W42 -> 44986 | AH42: =AR19 -> 195 | AI42: =AV19 -> 139 | AL42: =AG42 -> 44986 | AM42: =AJ19/$E19 -> 0.88495575 | AN42: =AK19/$E19 -> 0.07079646 | AO42: =AL19/$E19 -> 0.038348083 | AP42: =AM19/$E19 -> 0.0029498525 | AQ42: =AN19/$E19 -> 0.0029498525

Sheet ESA01 - GHI2
B2: Mês/ano | C2: Quant de eventos > 1000 W/m² | D2: Qt. de eventos > 1367 W/m² | E2: Total de eventos | F2: Qt. eventos < 30 segundos | >1000 e <1367 W/m² | G2: Valor médio dos eventos < 30 segundos | >1000 e <1367 W/m² | H2: Valor máximo dos eventos < 30 segundos | >1000 e <1367 W/m² | I2: Qt. eventos 30<->60 segundos | >1000 e <1367 W/m² | J2: Valor médio dos eventos 30<->60 segundos | >1000 e <1367 W/m² | K2: Valor máximo dos eventos 30<->60 segundos | >1000 e <1367 W/m² | L2: Qt. eventos 60<->120 segundos | >1000 e <1367 W/m² | M2: Valor médio dos eventos 60<->120 segundos | >1000 e <1367 W/m² | N2: Valor máximo dos eventos 60<->120 segundos | >1000 e <1367 W/m² | O2: Qt. eventos < 120<->180 segundos | >1000 e <1367 W/m² | P2: Valor médio dos eventos < 120<->180 segundos | >1000 e <1367 W/m² | Q2: Valor máximo dos eventos < 120<->180 segundos | >1000 e <1367 W/m² | R2: Qt. eventos > 180 segundos | >1000 e <1367 W/m² | S2: Valor médio dos eventos > 180 segundos | >1000 e <1367 W/m² | T2: Valor máximo dos eventos > 180 segundos | >1000 e <1367 W/m² | U2: Qt. eventos < 30 segundos | >1367 W/m² | V2: Valor médio dos eventos < 30 segundos | >1367 W/m² | W2: Valor máximo dos eventos < 30 segundos | >1367 W/m² | X2: Qt. eventos 30<->60 segundos | >1367 W/m² | Y2: Valor médio dos eventos 30<->60 segundos | >1367 W/m² | Z2: Valor máximo dos eventos 30<->60 segundos | >1367 W/m² | AA2: Qt. eventos 60<->120 segundos | >1367 W/m² | AB2: Valor médio dos eventos 60<->120 segundos | >1367 W/m² | AC2: Valor máximo dos eventos 60<->120 segundos | >1367 W/m² | AD2: Qt. eventos < 120<->180 segundos | >1367 W/m² | AE2: Valor médio dos eventos < 120<->180 segundos | >1367 W/m² | AF2: Valor máximo dos eventos < 120<->180 segundos | >1367 W/m² | AG2: Qt. eventos > 180 segundos | >1367 W/m² | AH2: Valor médio dos eventos > 180 segundos | >1367 W/m² | AI2: Valor máximo dos eventos > 180 segundos | >1367 W/m² | AJ2: Qt. eventos < 30 segundos | Total | AK2: Qt. eventos 30<->60 segundos | Total | AL2: Qt. eventos 60<->120 segundos | Total | AM2: Qt. eventos < 120<->180 segundos | Total | AN2: Qt. eventos > 180 segundos | Total | AO2: Hora/Dia do maior evento | AP2: Valor do maior evento em W/m² | AQ2: Dia/Hora do Evento de maior duração >1000 e <1367 W/m² | AR2: Duração do Evento >1000 e <1367 W/m² | AS2: Valor médio do evento de maior duração >1000 e < 1367 W/m² | AT2: Valor máximo do evento de maior duração >1000 e < 1367 W/m² | AU2: Dia/Hora do Evento de maior duração >1367 W/m² | AV2: Duração Evento >1367 W/m² | AW2: Valor médio do evento de maior duração >1000 e < 1367 W/m² | AX2: Valor máximo do evento de maior duração >1000 e < 1367 W/m²
B3: 44501 | C3: 31 | D3: 1 | E3: 32 | F3: 28 | G3: 1228.0224 | H3: 1365 | I3: 3 | J3: 1122.0459 | K3: 1186 | U3: 1 | V3: 1367.75 | W3: 1368 | AJ3: 29 | AK3: 3 | AO3: 44515.474 | AP3: 1368 | AQ3: 44516.39 | AR3: 45 | AS3: 1166.9333 | AT3: 1186 | AU3: 44515.474 | AV3: 4 | AW3: 1367.75 | AX3: 1368
B4: 44531 | C4: 207 | D4: 53 | E4: 260 | F4: 188 | G4: 1253.7812 | H4: 1366 | I4: 11 | J4: 1242.4543 | K4: 1366 | L4: 5 | M4: 1185.7094 | N4: 1328 | O4: 2 | P4: 1334.4212 | Q4: 1356 | R4: 1 | S4: 1354.4612 | T4: 1366 | U4: 50 | V4: 1400.677 | W4: 1613 | X4: 3 | Y4: 1389.2917 | Z4: 1440 | AJ4: 238 | AK4: 14 | AL4: 5 | AM4: 2 | AN4: 1 | AO4: 44544.454 | AP4: 1613 | AQ4: 44561.52 | AR4: 245 | AS4: 1354.4612 | AT4: 1366 | AU4: 44538.467 | AV4: 40 | AW4: 1377 | AX4: 1385
B5: 44562 | C5: 136 | D5: 95 | E5: 231 | F5: 124 | G5: 1285.9252 | H5: 1366 | I5: 8 | J5: 1268.6336 | K5: 1366 | L5: 4 | M5: 1172.9858 | N5: 1355 | U5: 80 | V5: 1399.4639 | W5: 1570 | X5: 12 | Y5: 1410.5695 | Z5: 1573 | AA5: 3 | AB5: 1465.2854 | AC5: 1543 | AJ5: 204 | AK5: 20 | AL5: 7 | AO5: 44576.488 | AP5: 1573 | AQ5: 44577.525 | AR5: 105 | AS5: 1345.4762 | AT5: 1355 | AU5: 44569.434 | AV5: 106 | AW5: 1469.6887 | AX5: 1516
B6: 44593 | C6: 68 | D6: 51 | E6: 119 | F6: 59 | G6: 1244.4539 | H6: 1366 | I6: 4 | J6: 1176.6391 | K6: 1365 | L6: 3 | M6: 1156.2548 | N6: 1366 | O6: 1 | P6: 1019.3013 | Q6: 1042 | R6: 1 | S6: 1346.3757 | T6: 1366 | U6: 42 | V6: 1412.6558 | W6: 1574 | X6: 4 | Y6: 1398.7779 | Z6: 1448 | AA6: 3 | AB6: 1399.6021 | AC6: 1426 | AD6: 2 | AE6: 1423.2575 | AF6: 1487 | AJ6: 101 | AK6: 8 | AL6: 6 | AM6: 3 | AN6: 1 | AO6: 44598.498 | AP6: 1574 | AQ6: 44598.541 | AR6: 189 | AS6: 1346.3757 | AT6: 1366 | AU6: 44598.455 | AV6: 134 | AW6: 1457.2836 | AX6: 1487
B7: 44621 | C7: 256 | D7: 143 | E7: 399 | F7: 233 | G7: 1265.2653 | H7: 1366 | I7: 15 | J7: 1202.7275 | K7: 1366 | L7: 7 | M7: 1236.0154 | N7: 1357 | O7: 1 | P7: 1108.2333 | Q7: 1132 | U7: 131 | V7: 1399.1804 | W7: 1557 | X7: 8 | Y7: 1394.8291 | Z7: 1499 | AA7: 4 | AB7: 1441.2463 | AC7: 1533 | AJ7: 364 | AK7: 23 | AL7: 11 | AM7: 1 | AO7: 44645.455 | AP7: 1557 | AQ7: 44633.59 | AR7: 180 | AS7: 1108.2333 | AT7: 1132 | AU7: 44633.503 | AV7: 95 | AW7: 1449.1053 | AX7: 1533
B8: 44652 | C8: 459 | D8: 82 | E8: 541 | F8: 435 | G8: 1236.6735 | H8: 1366 | I8: 16 | J8: 1234.9061 | K8: 1366 | L8: 7 | M8: 1241.6968 | N8: 1366 | O8: 1 | P8: 1146.6797 | Q8: 1166 | U8: 76 | V8: 1399.7183 | W8: 1503 | X8: 4 | Y8: 1423.2427 | Z8: 1482 | AD8: 1 | AE8: 1453.5263 | AF8: 1482 | AG8: 1 | AH8: 1433.582 | AI8: 1492 | AJ8: 511 | AK8: 20 | AL8: 7 | AM8: 2 | AN8: 1 | AO8: 44663.484 | AP8: 1503 | AQ8: 44667.402 | AR8: 128 | AS8: 1146.6797 | AT8: 1166 | AU8: 44652.516 | AV8: 256 | AW8: 1433.582 | AX8: 1492
B9: 44682 | C9: 436 | D9: 3 | E9: 439 | F9: 398 | G9: 1176.322 | H9: 1365 | I9: 29 | J9: 1193.0513 | K9: 1347 | L9: 6 | M9: 1180.8007 | N9: 1296 | O9: 1 | P9: 1169.9919 | Q9: 1245 | R9: 2 | S9: 1218.0658 | T9: 1252 | U9: 3 | V9: 1368.6667 | W9: 1371 | AJ9: 401 | AK9: 29 | AL9: 6 | AM9: 1 | AN9: 2 | AO9: 44708.497 | AP9: 1371 | AQ9: 44687.423 | AR9: 183 | AS9: 1216.8743 | AT9: 1252 | AU9: 44708.497 | AV9: 1 | AW9: 1371 | AX9: 1371
B10: 44713 | C10: 467 | D10: 1 | E10: 468 | F10: 424 | G10: 1134.1736 | H10: 1344 | I10: 29 | J10: 1152.8224 | K10: 1325 | L10: 13 | M10: 1182.4717 | N10: 1319 | O10: 1 | P10: 1225.5328 | Q10: 1271 | U10: 1 | V10: 1375.3333 | W10: 1380 | AJ10: 425 | AK10: 29 | AL10: 13 | AM10: 1 | AO10: 44718.499 | AP10: 1380 | AQ10: 44723.467 | AR10: 137 | AS10: 1225.5328 | AT10: 1271 | AU10: 44718.499 | AV10: 3 | AW10: 1375.3333 | AX10: 1380
B11: 44743 | C11: 431 | D11: 4 | E11: 435 | F11: 382 | G11: 1144.0687 | H11: 1365 | I11: 36 | J11: 1153.2739 | K11: 1333 | L11: 9 | M11: 1164.6318 | N11: 1278 | O11: 4 | P11: 1118.2151 | Q11: 1227 | U11: 4 | V11: 1406.5347 | W11: 1489 | AJ11: 386 | AK11: 36 | AL11: 9 | AM11: 4 | AO11: 44757.51 | AP11: 1489 | AQ11: 44769.46 | AR11: 160 | AS11: 1200.6875 | AT11: 1221 | AU11: 44757.51 | AV11: 14 | AW11: 1451.9286 | AX11: 1489
B12: 44774 | C12: 625 | D12: 74 | E12: 699 | F12: 576 | G12: 1203.0295 | H12: 1366 | I12: 35 | J12: 1222.781 | K12: 1366 | L12: 9 | M12: 1227.448 | N12: 1366 | O12: 5 | P12: 1235.5964 | Q12: 1347 | U12: 71 | V12: 1396.3019 | W12: 1469 | X12: 3 | Y12: 1396.8273 | Z12: 1445 | AJ12: 647 | AK12: 38 | AL12: 9 | AM12: 5 | AO12: 44788.458 | AP12: 1469 | AQ12: 44790.542 | AR12: 151 | AS12: 1218.3444 | AT12: 1234 | AU12: 44804.507 | AV12: 46 | AW12: 1406.587 | AX12: 1445
B13: 44805 | C13: 388 | D13: 61 | E13: 449 | F13: 340 | G13: 1200.0426 | H13: 1366 | I13: 35 | J13: 1196.7979 | K13: 1366 | L13: 10 | M13: 1198.8439 | N13: 1366 | O13: 3 | P13: 1245.8609 | Q13: 1365 | U13: 57 | V13: 1400.1187 | W13: 1513 | X13: 3 | Y13: 1433.9483 | Z13: 1471 | AA13: 1 | AB13: 1478.029 | AC13: 1503 | AJ13: 397 | AK13: 38 | AL13: 11 | AM13: 3 | AO13: 44826.441 | AP13: 1513 | AQ13: 44808.523 | AR13: 156 | AS13: 1328.1154 | AT13: 1365 | AU13: 44817.485 | AV13: 69 | AW13: 1478.029 | AX13: 1503
B14: 44835 | C14: 90 | D14: 50 | E14: 140 | F14: 86 | G14: 1277.0921 | H14: 1366 | I14: 3 | J14: 1245.7539 | K14: 1350 | L14: 1 | M14: 1044.9344 | N14: 1048 | U14: 42 | V14: 1392.2025 | W14: 1481 | X14: 7 | Y14: 1402.8054 | Z14: 1506 | AA14: 1 | AB14: 1399.9867 | AC14: 1419 | AJ14: 128 | AK14: 10 | AL14: 2 | AO14: 44858.459 | AP14: 1506 | AQ14: 44853.367 | AR14: 61 | AS14: 1044.9344 | AT14: 1048 | AU14: 44858.468 | AV14: 75 | AW14: 1399.9867 | AX14: 1419
B15: 44866 | C15: 223 | D15: 106 | E15: 329 | F15: 187 | G15: 1223.9837 | H15: 1366 | I15: 15 | J15: 1130.8933 | K15: 1361 | L15: 17 | M15: 1213.1562 | N15: 1361 | O15: 4 | P15: 1266.1559 | Q15: 1366 | U15: 92 | V15: 1420.0104 | W15: 1651 | X15: 7 | Y15: 1414.9484 | Z15: 1517 | AA15: 7 | AB15: 1417.1313 | AC15: 1516 | AJ15: 279 | AK15: 22 | AL15: 24 | AM15: 4 | AO15: 44870.503 | AP15: 1651 | AQ15: 44874.401 | AR15: 468 | AS15: 1193.9594 | AT15: 1228 | AU15: 44871.514 | AV15: 107 | AW15: 1495.2056 | AX15: 1516
B16: 44896 | C16: 212 | D16: 63 | E16: 275 | F16: 196 | G16: 1223.7569 | H16: 1366 | I16: 10 | J16: 1250.7457 | K16: 1366 | L16: 3 | M16: 1212.6264 | N16: 1366 | O16: 3 | P16: 1137.4433 | Q16: 1258 | U16: 54 | V16: 1395.2654 | W16: 1571 | X16: 5 | Y16: 1396.1912 | Z16: 1457 | AA16: 3 | AB16: 1406.0434 | AC16: 1445 | AD16: 1 | AE16: 1395.6312 | AF16: 1422 | AJ16: 250 | AK16: 15 | AL16: 6 | AM16: 4 | AO16: 44900.486 | AP16: 1571 | AQ16: 44916.437 | AR16: 264 | AS16: 1345.3939 | AT16: 1362 | AU16: 44916.468 | AV16: 160 | AW16: 1395.6312 | AX16: 1422
B17: 44927 | C17: 69 | D17: 17 | E17: 86 | F17: 64 | G17: 1239.1028 | H17: 1366 | I17: 4 | J17: 1253.0154 | K17: 1366 | L17: 1 | M17: 1303.2571 | N17: 1320 | U17: 16 | V17: 1379.4508 | W17: 1403 | AA17: 1 | AB17: 1384.5246 | AC17: 1393 | AJ17: 80 | AK17: 4 | AL17: 2 | AO17: 44954.449 | AP17: 1403 | AQ17: 44949.425 | AR17: 105 | AS17: 1303.2571 | AT17: 1320 | AU17: 44943.47 | AV17: 61 | AW17: 1384.5246 | AX17: 1393
B18: 44958 | C18: 96 | D18: 97 | E18: 193 | F18: 90 | G18: 1244.6235 | H18: 1366 | I18: 2 | J18: 1251.2102 | K18: 1326 | L18: 2 | M18: 1335.7704 | N18: 1345 | R18: 2 | S18: 1189.7939 | T18: 1266 | U18: 91 | V18: 1404.6748 | W18: 1550 | X18: 4 | Y18: 1422.6086 | Z18: 1475 | AA18: 1 | AB18: 1409.0614 | AC18: 1422 | AD18: 1 | AE18: 1431.2126 | AF18: 1489 | AJ18: 181 | AK18: 6 | AL18: 3 | AM18: 1 | AN18: 2 | AO18: 44958.501 | AP18: 1550 | AQ18: 44965.583 | AR18: 1979 | AS18: 1199.5331 | AT18: 1266 | AU18: 44979.499 | AV18: 127 | AW18: 1431.2126 | AX18: 1489
B19: 44986 | C19: 229 | D19: 80 | E19: 309 | F19: 209 | G19: 1269.4259 | H19: 1366 | I19: 12 | J19: 1207.8286 | K19: 1366 | L19: 7 | M19: 1242.338 | N19: 1366 | R19: 1 | S19: 1172.9734 | T19: 1258 | U19: 69 | V19: 1404.2476 | W19: 1551 | X19: 5 | Y19: 1405.7478 | Z19: 1520 | AA19: 6 | AB19: 1420.5959 | AC19: 1511 | AJ19: 278 | AK19: 17 | AL19: 13 | AN19: 1 | AO19: 45010.505 | AP19: 1551 | AQ19: 45004.38 | AR19: 188 | AS19: 1172.9734 | AT19: 1258 | AU19: 45004.446 | AV19: 113 | AW19: 1381.292 | AX19: 1394
B25: Mês/ano | C25: Ocorrências | E25: Mês/ano | F25: 1000 ≥ Ig < 1300 W/m² | G25: Ig > 1367 W/m² | I25: Mês/ano | J25: < 30 seg | K25: < 1 min | L25: < 2 minutos | M25: < 3 minutos | N25: ≥ 3 minutos | P25: =I25 -> Mês/ano | Q25: < 30 seg | R25: < 1 min | S25: < 2 minutos | T25: < 3 minutos | U25: ≥ 3 minutos | W25: =P25 -> Mês/ano | X25: < 30 seg | Y25: < 1 min | Z25: < 2 minutos | AA25: < 3 minutos | AB25: ≥ 3 minutos | AD25: Dia/mês | AE25: Evento de maior magnitude [W/m²] | AF25: ="" | AG25: Dia/mês | AH25: Maior duração >1000 e <1367 [W/m²] | AI25: Maior duração >1367 [W/m²] | AJ25: ="" | AL25: Mês/ano | AM25: < 30 seg | AN25: < 1 min | AO25: < 2 minutos | AP25: < 3 minutos | AQ25: ≥ 3 minutos
B26: =B3 -> 44501 | C26: =E3 -> 32 | E26: =B26 -> 44501 | F26: =C3/E3 -> 0.96875 | G26: =D3/E3 -> 0.03125 | I26: =E26 -> 44501 | J26: =AJ3/$E3 -> 0.90625 | K26: =AK3/$E3 -> 0.09375 | L26: =AL3/$E3 -> 0 | M26: =AM3/$E3 -> 0 | N26: =AN3/$E3 -> 0 | P26: =I26 -> 44501 | Q26: =G3 -> 1228.0224 | R26: =J3 -> 1122.0459 | S26: =M3 | T26: =P3 | U26: =S3 | W26: =P26 -> 44501 | X26: =V3 -> 1367.75 | Y26: =Y3 | Z26: =AB3 | AA26: =AE3 | AB26: =AH3 | AD26: =W26 -> 44501 | AE26: =AP3 -> 1368 | AG26: =W26 -> 44501 | AH26: =AR3 -> 45 | AI26: =AV3 -> 4 | AL26: =AG26 -> 44501 | AM26: =AJ3/$E3 -> 0.90625 | AN26: =AK3/$E3 -> 0.09375 | AO26: =AL3/$E3 -> 0 | AP26: =AM3/$E3 -> 0 | AQ26: =AN3/$E3 -> 0
B27: =B4 -> 44531 | C27: =E4 -> 260 | E27: =B27 -> 44531 | F27: =C4/E4 -> 0.79615385 | G27: =D4/E4 -> 0.20384615 | I27: =E27 -> 44531 | J27: =AJ4/$E4 -> 0.91538462 | K27: =AK4/$E4 -> 0.053846154 | L27: =AL4/$E4 -> 0.019230769 | M27: =AM4/$E4 -> 0.0076923077 | N27: =AN4/$E4 -> 0.0038461538 | P27: =I27 -> 44531 | Q27: =G4 -> 1253.7812 | R27: =J4 -> 1242.4543 | S27: =M4 -> 1185.7094 | T27: =P4 -> 1334.4212 | U27: =S4 -> 1354.4612 | W27: =P27 -> 44531 | X27: =V4 -> 1400.677 | Y27: =Y4 -> 1389.2917 | Z27: =AB4 | AA27: =AE4 | AB27: =AH4 | AD27: =AO4 -> 44544.454 | AE27: =AP4 -> 1613 | AG27: =W27 -> 44531 | AH27: =AR4 -> 245 | AI27: =AV4 -> 40 | AL27: =AG27 -> 44531 | AM27: =AJ4/$E4 -> 0.91538462 | AN27: =AK4/$E4 -> 0.053846154 | AO27: =AL4/$E4 -> 0.019230769 | AP27: =AM4/$E4 -> 0.0076923077 | AQ27: =AN4/$E4 -> 0.0038461538
B28: =B5 -> 44562 | C28: =E5 -> 231 | E28: =B28 -> 44562 | F28: =C5/E5 -> 0.58874459 | G28: =D5/E5 -> 0.41125541 | I28: =E28 -> 44562 | J28: =AJ5/$E5 -> 0.88311688 | K28: =AK5/$E5 -> 0.086580087 | L28: =AL5/$E5 -> 0.03030303 | M28: =AM5/$E5 -> 0 | N28: =AN5/$E5 -> 0 | P28: =I28 -> 44562 | Q28: =G5 -> 1285.9252 | R28: =J5 -> 1268.6336 | S28: =M5 -> 1172.9858 | T28: =P5 | U28: =S5 | W28: =P28 -> 44562 | X28: =V5 -> 1399.4639 | Y28: =Y5 -> 1410.5695 | Z28: =AB5 -> 1465.2854 | AA28: =AE5 | AB28: =AH5 | AD28: =AO5 -> 44576.488 | AE28: =AP5 -> 1573 | AG28: =W28 -> 44562 | AH28: =AR5 -> 105 | AI28: =AV5 -> 106 | AL28: =AG28 -> 44562 | AM28: =AJ5/$E5 -> 0.88311688 | AN28: =AK5/$E5 -> 0.086580087 | AO28: =AL5/$E5 -> 0.03030303 | AP28: =AM5/$E5 -> 0 | AQ28: =AN5/$E5 -> 0
B29: =B6 -> 44593 | C29: =E6 -> 119 | E29: =B29 -> 44593 | F29: =C6/E6 -> 0.57142857 | G29: =D6/E6 -> 0.42857143 | I29: =E29 -> 44593 | J29: =AJ6/$E6 -> 0.8487395 | K29: =AK6/$E6 -> 0.067226891 | L29: =AL6/$E6 -> 0.050420168 | M29: =AM6/$E6 -> 0.025210084 | N29: =AN6/$E6 -> 0.0084033613 | P29: =I29 -> 44593 | Q29: =G6 -> 1244.4539 | R29: =J6 -> 1176.6391 | S29: =M6 -> 1156.2548 | T29: =P6 -> 1019.3013 | U29: =S6 -> 1346.3757 | W29: =P29 -> 44593 | X29: =V6 -> 1412.6558 | Y29: =Y6 -> 1398.7779 | Z29: =AB6 -> 1399.6021 | AA29: =AE6 -> 1423.2575 | AB29: =AH6 | AD29: =AO6 -> 44598.498 | AE29: =AP6 -> 1574 | AG29: =W29 -> 44593 | AH29: =AR6 -> 189 | AI29: =AV6 -> 134 | AL29: =AG29 -> 44593 | AM29: =AJ6/$E6 -> 0.8487395 | AN29: =AK6/$E6 -> 0.067226891 | AO29: =AL6/$E6 -> 0.050420168 | AP29: =AM6/$E6 -> 0.025210084 | AQ29: =AN6/$E6 -> 0.0084033613
B30: =B7 -> 44621 | C30: =E7 -> 399 | E30: =B30 -> 44621 | F30: =C7/E7 -> 0.64160401 | G30: =D7/E7 -> 0.35839599 | I30: =E30 -> 44621 | J30: =AJ7/$E7 -> 0.9122807 | K30: =AK7/$E7 -> 0.05764411 | L30: =AL7/$E7 -> 0.027568922 | M30: =AM7/$E7 -> 0.0025062657 | N30: =AN7/$E7 -> 0 | P30: =I30 -> 44621 | Q30: =G7 -> 1265.2653 | R30: =J7 -> 1202.7275 | S30: =M7 -> 1236.0154 | T30: =P7 -> 1108.2333 | U30: =S7 | W30: =P30 -> 44621 | X30: =V7 -> 1399.1804 | Y30: =Y7 -> 1394.8291 | Z30: =AB7 -> 1441.2463 | AA30: =AE7 | AB30: =AH7 | AD30: =AO7 -> 44645.455 | AE30: =AP7 -> 1557 | AG30: =W30 -> 44621 | AH30: =AR7 -> 180 | AI30: =AV7 -> 95 | AL30: =AG30 -> 44621 | AM30: =AJ7/$E7 -> 0.9122807 | AN30: =AK7/$E7 -> 0.05764411 | AO30: =AL7/$E7 -> 0.027568922 | AP30: =AM7/$E7 -> 0.0025062657 | AQ30: =AN7/$E7 -> 0
B31: =B8 -> 44652 | C31: =E8 -> 541 | E31: =B31 -> 44652 | F31: =C8/E8 -> 0.84842884 | G31: =D8/E8 -> 0.15157116 | I31: =E31 -> 44652 | J31: =AJ8/$E8 -> 0.94454713 | K31: =AK8/$E8 -> 0.036968577 | L31: =AL8/$E8 -> 0.012939002 | M31: =AM8/$E8 -> 0.0036968577 | N31: =AN8/$E8 -> 0.0018484288 | P31: =I31 -> 44652 | Q31: =G8 -> 1236.6735 | R31: =J8 -> 1234.9061 | S31: =M8 -> 1241.6968 | T31: =P8 -> 1146.6797 | U31: =S8 | W31: =P31 -> 44652 | X31: =V8 -> 1399.7183 | Y31: =Y8 -> 1423.2427 | Z31: =AB8 | AA31: =AE8 -> 1453.5263 | AB31: =AH8 -> 1433.582 | AD31: =AO8 -> 44663.484 | AE31: =AP8 -> 1503 | AG31: =W31 -> 44652 | AH31: =AR8 -> 128 | AI31: =AV8 -> 256 | AL31: =AG31 -> 44652 | AM31: =AJ8/$E8 -> 0.94454713 | AN31: =AK8/$E8 -> 0.036968577 | AO31: =AL8/$E8 -> 0.012939002 | AP31: =AM8/$E8 -> 0.0036968577 | AQ31: =AN8/$E8 -> 0.0018484288
B32: =B9 -> 44682 | C32: =E9 -> 439 | E32: =B32 -> 44682 | F32: =C9/E9 -> 0.99316629 | G32: =D9/E9 -> 0.006833713 | I32: =E32 -> 44682 | J32: =AJ9/$E9 -> 0.91343964 | K32: =AK9/$E9 -> 0.066059226 | L32: =AL9/$E9 -> 0.013667426 | M32: =AM9/$E9 -> 0.0022779043 | N32: =AN9/$E9 -> 0.0045558087 | P32: =I32 -> 44682 | Q32: =G9 -> 1176.322 | R32: =J9 -> 1193.0513 | S32: =M9 -> 1180.8007 | T32: =P9 -> 1169.9919 | U32: =S9 -> 1218.0658 | W32: =P32 -> 44682 | X32: =V9 -> 1368.6667 | Y32: =Y9 | Z32: =AB9 | AA32: =AE9 | AB32: =AH9 | AD32: =AO9 -> 44708.497 | AE32: =AP9 -> 1371 | AG32: =W32 -> 44682 | AH32: =AR9 -> 183 | AI32: =AV9 -> 1 | AL32: =AG32 -> 44682 | AM32: =AJ9/$E9 -> 0.91343964 | AN32: =AK9/$E9 -> 0.066059226 | AO32: =AL9/$E9 -> 0.013667426 | AP32: =AM9/$E9 -> 0.0022779043 | AQ32: =AN9/$E9 -> 0.0045558087
B33: =B10 -> 44713 | C33: =E10 -> 468 | E33: =B33 -> 44713 | F33: =C10/E10 -> 0.99786325 | G33: =D10/E10 -> 0.0021367521 | I33: =E33 -> 44713 | J33: =AJ10/$E10 -> 0.90811966 | K33: =AK10/$E10 -> 0.061965812 | L33: =AL10/$E10 -> 0.027777778 | M33: =AM10/$E10 -> 0.0021367521 | N33: =AN10/$E10 -> 0 | P33: =I33 -> 44713 | Q33: =G10 -> 1134.1736 | R33: =J10 -> 1152.8224 | S33: =M10 -> 1182.4717 | T33: =P10 -> 1225.5328 | U33: =S10 | W33: =P33 -> 44713 | X33: =V10 -> 1375.3333 | Y33: =Y10 | Z33: =AB10 | AA33: =AE10 | AB33: =AH10 | AD33: =AO10 -> 44718.499 | AE33: =AP10 -> 1380 | AG33: =W33 -> 44713 | AH33: =AR10 -> 137 | AI33: =AV10 -> 3 | AL33: =AG33 -> 44713 | AM33: =AJ10/$E10 -> 0.90811966 | AN33: =AK10/$E10 -> 0.061965812 | AO33: =AL10/$E10 -> 0.027777778 | AP33: =AM10/$E10 -> 0.0021367521 | AQ33: =AN10/$E10 -> 0
B34: =B11 -> 44743 | C34: =E11 -> 435 | E34: =B34 -> 44743 | F34: =C11/E11 -> 0.9908046 | G34: =D11/E11 -> 0.0091954023 | I34: =E34 -> 44743 | J34: =AJ11/$E11 -> 0.88735632 | K34: =AK11/$E11 -> 0.082758621 | L34: =AL11/$E11 -> 0.020689655 | M34: =AM11/$E11 -> 0.0091954023 | N34: =AN11/$E11 -> 0 | P34: =I34 -> 44743 | Q34: =G11 -> 1144.0687 | R34: =J11 -> 1153.2739 | S34: =M11 -> 1164.6318 | T34: =P11 -> 1118.2151 | U34: =S11 | W34: =P34 -> 44743 | X34: =V11 -> 1406.5347 | Y34: =Y11 | Z34: =AB11 | AA34: =AE11 | AB34: =AH11 | AD34: =AO11 -> 44757.51 | AE34: =AP11 -> 1489 | AG34: =W34 -> 44743 | AH34: =AR11 -> 160 | AI34: =AV11 -> 14 | AL34: =AG34 -> 44743 | AM34: =AJ11/$E11 -> 0.88735632 | AN34: =AK11/$E11 -> 0.082758621 | AO34: =AL11/$E11 -> 0.020689655 | AP34: =AM11/$E11 -> 0.0091954023 | AQ34: =AN11/$E11 -> 0
B35: =B12 -> 44774 | C35: =E12 -> 699 | E35: =B35 -> 44774 | F35: =C12/E12 -> 0.89413448 | G35: =D12/E12 -> 0.10586552 | I35: =E35 -> 44774 | J35: =AJ12/$E12 -> 0.92560801 | K35: =AK12/$E12 -> 0.054363376 | L35: =AL12/$E12 -> 0.012875536 | M35: =AM12/$E12 -> 0.0071530758 | N35: =AN12/$E12 -> 0 | P35: =I35 -> 44774 | Q35: =G12 -> 1203.0295 | R35: =J12 -> 1222.781 | S35: =M12 -> 1227.448 | T35: =P12 -> 1235.5964 | U35: =S12 | W35: =P35 -> 44774 | X35: =V12 -> 1396.3019 | Y35: =Y12 -> 1396.8273 | Z35: =AB12 | AA35: =AE12 | AB35: =AH12 | AD35: =AO12 -> 44788.458 | AE35: =AP12 -> 1469 | AG35: =W35 -> 44774 | AH35: =AR12 -> 151 | AI35: =AV12 -> 46 | AL35: =AG35 -> 44774 | AM35: =AJ12/$E12 -> 0.92560801 | AN35: =AK12/$E12 -> 0.054363376 | AO35: =AL12/$E12 -> 0.012875536 | AP35: =AM12/$E12 -> 0.0071530758 | AQ35: =AN12/$E12 -> 0
B36: =B13 -> 44805 | C36: =E13 -> 449 | E36: =B36 -> 44805 | F36: =C13/E13 -> 0.86414254 | G36: =D13/E13 -> 0.13585746 | I36: =E36 -> 44805 | J36: =AJ13/$E13 -> 0.88418708 | K36: =AK13/$E13 -> 0.084632517 | L36: =AL13/$E13 -> 0.024498886 | M36: =AM13/$E13 -> 0.0066815145 | N36: =AN13/$E13 -> 0 | P36: =I36 -> 44805 | Q36: =G13 -> 1200.0426 | R36: =J13 -> 1196.7979 | S36: =M13 -> 1198.8439 | T36: =P13 -> 1245.8609 | U36: =S13 | W36: =P36 -> 44805 | X36: =V13 -> 1400.1187 | Y36: =Y13 -> 1433.9483 | Z36: =AB13 -> 1478.029 | AA36: =AE13 | AB36: =AH13 | AD36: =AO13 -> 44826.441 | AE36: =AP13 -> 1513 | AG36: =W36 -> 44805 | AH36: =AR13 -> 156 | AI36: =AV13 -> 69 | AL36: =AG36 -> 44805 | AM36: =AJ13/$E13 -> 0.88418708 | AN36: =AK13/$E13 -> 0.084632517 | AO36: =AL13/$E13 -> 0.024498886 | AP36: =AM13/$E13 -> 0.0066815145 | AQ36: =AN13/$E13 -> 0
B37: =B14 -> 44835 | C37: =E14 -> 140 | E37: =B37 -> 44835 | F37: =C14/E14 -> 0.64285714 | G37: =D14/E14 -> 0.35714286 | I37: =E37 -> 44835 | J37: =AJ14/$E14 -> 0.91428571 | K37: =AK14/$E14 -> 0.071428571 | L37: =AL14/$E14 -> 0.014285714 | M37: =AM14/$E14 -> 0 | N37: =AN14/$E14 -> 0 | P37: =I37 -> 44835 | Q37: =G14 -> 1277.0921 | R37: =J14 -> 1245.7539 | S37: =M14 -> 1044.9344 | T37: =P14 | U37: =S14 | W37: =P37 -> 44835 | X37: =V14 -> 1392.2025 | Y37: =Y14 -> 1402.8054 | Z37: =AB14 -> 1399.9867 | AA37: =AE14 | AB37: =AH14 | AD37: =AO14 -> 44858.459 | AE37: =AP14 -> 1506 | AG37: =W37 -> 44835 | AH37: =AR14 -> 61 | AI37: =AV14 -> 75 | AL37: =AG37 -> 44835 | AM37: =AJ14/$E14 -> 0.91428571 | AN37: =AK14/$E14 -> 0.071428571 | AO37: =AL14/$E14 -> 0.014285714 | AP37: =AM14/$E14 -> 0 | AQ37: =AN14/$E14 -> 0
B38: =B15 -> 44866 | C38: =E15 -> 329 | E38: =B38 -> 44866 | F38: =C15/E15 -> 0.67781155 | G38: =D15/E15 -> 0.32218845 | I38: =E38 -> 44866 | J38: =AJ15/$E15 -> 0.84802432 | K38: =AK15/$E15 -> 0.066869301 | L38: =AL15/$E15 -> 0.072948328 | M38: =AM15/$E15 -> 0.012158055 | N38: =AN15/$E15 -> 0 | P38: =I38 -> 44866 | Q38: =G15 -> 1223.9837 | R38: =J15 -> 1130.8933 | S38: =M15 -> 1213.1562 | T38: =P15 -> 1266.1559 | U38: =S15 | W38: =P38 -> 44866 | X38: =V15 -> 1420.0104 | Y38: =Y15 -> 1414.9484 | Z38: =AB15 -> 1417.1313 | AA38: =AE15 | AB38: =AH15 | AD38: =AO15 -> 44870.503 | AE38: =AP15 -> 1651 | AG38: =W38 -> 44866 | AH38: =AR15 -> 468 | AI38: =AV15 -> 107 | AL38: =AG38 -> 44866 | AM38: =AJ15/$E15 -> 0.84802432 | AN38: =AK15/$E15 -> 0.066869301 | AO38: =AL15/$E15 -> 0.072948328 | AP38: =AM15/$E15 -> 0.012158055 | AQ38: =AN15/$E15 -> 0
... B42: =B19 -> 44986 | C42: =E19 -> 309 | E42: =B42 -> 44986 | F42: =C19/E19 -> 0.74110032 | G42: =D19/E19 -> 0.25889968 | I42: =E42 -> 44986 | J42: =AJ19/$E19 -> 0.89967638 | K42: =AK19/$E19 -> 0.055016181 | L42: =AL19/$E19 -> 0.042071197 | M42: =AM19/$E19 -> 0 | N42: =AN19/$E19 -> 0.003236246 | P42: =I42 -> 44986 | Q42: =G19 -> 1269.4259 | R42: =J19 -> 1207.8286 | S42: =M19 -> 1242.338 | T42: =P19 | U42: =S19 -> 1172.9734 | W42: =P42 -> 44986 | X42: =V19 -> 1404.2476 | Y42: =Y19 -> 1405.7478 | Z42: =AB19 -> 1420.5959 | AA42: =AE19 | AB42: =AH19 | AD42: =AO19 -> 45010.505 | AE42: =AP19 -> 1551 | AG42: =W42 -> 44986 | AH42: =AR19 -> 188 | AI42: =AV19 -> 113 | AL42: =AG42 -> 44986 | AM42: =AJ19/$E19 -> 0.89967638 | AN42: =AK19/$E19 -> 0.055016181 | AO42: =AL19/$E19 -> 0.042071197 | AP42: =AM19/$E19 -> 0 | AQ42: =AN19/$E19 -> 0.003236246

Sheet ESA01 - GHI3
B2: Mês/ano | C2: Quant de eventos > 1000 W/m² | D2: Qt. de eventos > 1367 W/m² | E2: Total de eventos | F2: Qt. eventos < 30 segundos | >1000 e <1367 W/m² | G2: Valor médio dos eventos < 30 segundos | >1000 e <1367 W/m² | H2: Valor máximo dos eventos < 30 segundos | >1000 e <1367 W/m² | I2: Qt. eventos 30<->60 segundos | >1000 e <1367 W/m² | J2: Valor médio dos eventos 30<->60 segundos | >1000 e <1367 W/m² | K2: Valor máximo dos eventos 30<->60 segundos | >1000 e <1367 W/m² | L2: Qt. eventos 60<->120 segundos | >1000 e <1367 W/m² | M2: Valor médio dos eventos 60<->120 segundos | >1000 e <1367 W/m² | N2: Valor máximo dos eventos 60<->120 segundos | >1000 e <1367 W/m² | O2: Qt. eventos < 120<->180 segundos | >1000 e <1367 W/m² | P2: Valor médio dos eventos < 120<->180 segundos | >1000 e <1367 W/m² | Q2: Valor máximo dos eventos < 120<->180 segundos | >1000 e <1367 W/m² | R2: Qt. eventos > 180 segundos | >1000 e <1367 W/m² | S2: Valor médio dos eventos > 180 segundos | >1000 e <1367 W/m² | T2: Valor máximo dos eventos > 180 segundos | >1000 e <1367 W/m² | U2: Qt. eventos < 30 segundos | >1367 W/m² | V2: Valor médio dos eventos < 30 segundos | >1367 W/m² | W2: Valor máximo dos eventos < 30 segundos | >1367 W/m² | X2: Qt. eventos 30<->60 segundos | >1367 W/m² | Y2: Valor médio dos eventos 30<->60 segundos | >1367 W/m² | Z2: Valor máximo dos eventos 30<->60 segundos | >1367 W/m² | AA2: Qt. eventos 60<->120 segundos | >1367 W/m² | AB2: Valor médio dos eventos 60<->120 segundos | >1367 W/m² | AC2: Valor máximo dos eventos 60<->120 segundos | >1367 W/m² | AD2: Qt. eventos < 120<->180 segundos | >1367 W/m² | AE2: Valor médio dos eventos < 120<->180 segundos | >1367 W/m² | AF2: Valor máximo dos eventos < 120<->180 segundos | >1367 W/m² | AG2: Qt. eventos > 180 segundos | >1367 W/m² | AH2: Valor médio dos eventos > 180 segundos | >1367 W/m² | AI2: Valor máximo dos eventos > 180 segundos | >1367 W/m² | AJ2: Qt. eventos < 30 segundos | Total | AK2: Qt. eventos 30<->60 segundos | Total | AL2: Qt. eventos 60<->120 segundos | Total | AM2: Qt. eventos < 120<->180 segundos | Total | AN2: Qt. eventos > 180 segundos | Total | AO2: Hora/Dia do maior evento | AP2: Valor do maior evento em W/m² | AQ2: Dia/Hora do Evento de maior duração >1000 e <1367 W/m² | AR2: Duração do Evento >1000 e <1367 W/m² | AS2: Valor médio do evento de maior duração >1000 e < 1367 W/m² | AT2: Valor máximo do evento de maior duração >1000 e < 1367 W/m² | AU2: Dia/Hora do Evento de maior duração >1367 W/m² | AV2: Duração Evento >1367 W/m² | AW2: Valor médio do evento de maior duração >1000 e < 1367 W/m² | AX2: Valor máximo do evento de maior duração >1000 e < 1367 W/m²
B3: 44501
B4: 44531
B5: 44562
B6: 44593
B7: 44621 | C7: 193 | D7: 102 | E7: 295 | F7: 185 | G7: 1268.8487 | H7: 1366 | I7: 7 | J7: 1221.6485 | K7: 1331 | L7: 1 | M7: 1327.7582 | N7: 1339 | U7: 97 | V7: 1391.9232 | W7: 1528 | X7: 3 | Y7: 1412.6719 | Z7: 1501 | AA7: 2 | AB7: 1442.4992 | AC7: 1498 | AJ7: 282 | AK7: 10 | AL7: 3 | AO7: 44645.457 | AP7: 1528 | AQ7: 44644.532 | AR7: 91 | AS7: 1327.7582 | AT7: 1339 | AU7: 44622.455 | AV7: 84 | AW7: 1433.0119 | AX7: 1458
B8: 44652 | C8: 394 | D8: 72 | E8: 466 | F8: 381 | G8: 1239.2594 | H8: 1366 | I8: 11 | J8: 1279.9811 | K8: 1365 | L8: 2 | M8: 1106.5945 | N8: 1211 | U8: 66 | V8: 1394.0556 | W8: 1490 | X8: 3 | Y8: 1399.8409 | Z8: 1450 | AA8: 2 | AB8: 1410.9899 | AC8: 1457 | AD8: 1 | AE8: 1419.5954 | AF8: 1446 | AJ8: 447 | AK8: 14 | AL8: 4 | AM8: 1 | AO8: 44677.455 | AP8: 1490 | AQ8: 44665.404 | AR8: 81 | AS8: 1190.0864 | AT8: 1211 | AU8: 44652.519 | AV8: 131 | AW8: 1419.5954 | AX8: 1446
B9: 44682 | C9: 404 | D9: 1 | E9: 405 | F9: 386 | G9: 1172.7135 | H9: 1360 | I9: 15 | J9: 1172.7586 | K9: 1300 | L9: 2 | M9: 1137.6488 | N9: 1212 | O9: 1 | P9: 1178.8713 | Q9: 1201 | U9: 1 | V9: 1376 | W9: 1376 | AJ9: 387 | AK9: 15 | AL9: 2 | AM9: 1 | AO9: 44708.497 | AP9: 1376 | AQ9: 44687.426 | AR9: 171 | AS9: 1178.8713 | AT9: 1201 | AU9: 44708.497 | AV9: 1 | AW9: 1376 | AX9: 1376
B10: 44713 | C10: 421 | E10: 421 | F10: 399 | G10: 1134.6042 | H10: 1358 | I10: 16 | J10: 1155.4687 | K10: 1282 | L10: 5 | M10: 1185.5667 | N10: 1279 | O10: 1 | P10: 1195.3008 | Q10: 1240 | AJ10: 399 | AK10: 16 | AL10: 5 | AM10: 1 | AO10: 44718.499 | AP10: 1358 | AQ10: 44723.466 | AR10: 133 | AS10: 1195.3008 | AT10: 1240 | AU10: 0 | AV10: 0 | AW10: 0 | AX10: 0
B11: 44743 | C11: 453 | D11: 1 | E11: 454 | F11: 431 | G11: 1137.1273 | H11: 1349 | I11: 20 | J11: 1156.6566 | K11: 1355 | L11: 2 | M11: 1125.9975 | N11: 1244 | U11: 1 | V11: 1420.7692 | W11: 1446 | AJ11: 432 | AK11: 20 | AL11: 2 | AO11: 44757.51 | AP11: 1446 | AQ11: 44766.395 | AR11: 89 | AS11: 1046.0674 | AT11: 1055 | AU11: 44757.51 | AV11: 13 | AW11: 1420.7692 | AX11: 1446
B12: 44774 | C12: 615 | D12: 64 | E12: 679 | F12: 587 | G12: 1204.0334 | H12: 1366 | I12: 20 | J12: 1242.709 | K12: 1362 | L12: 4 | M12: 1269.2432 | N12: 1361 | O12: 4 | P12: 1228.5418 | Q12: 1350 | U12: 64 | V12: 1392.8365 | W12: 1476 | AJ12: 651 | AK12: 20 | AL12: 4 | AM12: 4 | AO12: 44790.476 | AP12: 1476 | AQ12: 44790.542 | AR12: 150 | AS12: 1185.7133 | AT12: 1208 | AU12: 44804.506 | AV12: 26 | AW12: 1380.3462 | AX12: 1397
B13: 44805 | C13: 356 | D13: 52 | E13: 408 | F13: 332 | G13: 1198.4092 | H13: 1366 | I13: 15 | J13: 1196.0836 | K13: 1353 | L13: 9 | M13: 1256.3983 | N13: 1351 | U13: 48 | V13: 1408.5819 | W13: 1492 | X13: 4 | Y13: 1418.4995 | Z13: 1485 | AJ13: 380 | AK13: 19 | AL13: 9 | AO13: 44826.441 | AP13: 1492 | AQ13: 44819.412 | AR13: 119 | AS13: 1273.916 | AT13: 1306 | AU13: 44810.451 | AV13: 60 | AW13: 1381.45 | AX13: 1400
B14: 44835 | C14: 75 | D14: 42 | E14: 117 | F14: 73 | G14: 1279.1583 | H14: 1366 | I14: 2 | J14: 1319.0694 | K14: 1363 | U14: 38 | V14: 1399.3822 | W14: 1460 | X14: 4 | Y14: 1390.558 | Z14: 1481 | AJ14: 111 | AK14: 6 | AO14: 44858.459 | AP14: 1481 | AQ14: 44853.408 | AR14: 38 | AS14: 1328.1579 | AT14: 1363 | AU14: 44858.466 | AV14: 35 | AW14: 1398.2571 | AX14: 1418
B15: 44866 | C15: 227 | D15: 96 | E15: 323 | F15: 199 | G15: 1193.8093 | H15: 1366 | I15: 11 | J15: 1217.8807 | K15: 1364 | L15: 15 | M15: 1203.0473 | N15: 1365 | O15: 1 | P15: 1140.8235 | Q15: 1175 | R15: 1 | S15: 1175.7253 | T15: 1197 | U15: 90 | V15: 1417.8983 | W15: 1602 | X15: 3 | Y15: 1421.3052 | Z15: 1491 | AA15: 3 | AB15: 1425.0485 | AC15: 1482 | AJ15: 289 | AK15: 14 | AL15: 18 | AM15: 1 | AN15: 1 | AO15: 44870.503 | AP15: 1602 | AQ15: 44878.384 | AR15: 272 | AS15: 1101.386 | AT15: 1135 | AU15: 44871.514 | AV15: 101 | AW15: 1467.5248 | AX15: 1482
B16: 44896 | C16: 173 | D16: 60 | E16: 233 | F16: 160 | G16: 1227.7257 | H16: 1366 | I16: 7 | J16: 1220.4741 | K16: 1366 | L16: 5 | M16: 1199.751 | N16: 1364 | R16: 1 | S16: 1321.0539 | T16: 1330 | U16: 58 | V16: 1394.3813 | W16: 1563 | AA16: 2 | AB16: 1388.5 | AC16: 1417 | AJ16: 218 | AK16: 7 | AL16: 7 | AN16: 1 | AO16: 44900.477 | AP16: 1563 | AQ16: 44916.437 | AR16: 204 | AS16: 1321.0539 | AT16: 1330 | AU16: 44898.456 | AV16: 81 | AW16: 1395 | AX16: 1417
B17: 44927 | C17: 42 | D17: 6 | E17: 48 | F17: 42 | G17: 1274.1958 | H17: 1366 | U17: 6 | V17: 1373.3194 | W17: 1406 | AJ17: 48 | AO17: 44954.447 | AP17: 1406 | AQ17: 44949.436 | AR17: 20 | AS17: 1333.6 | AT17: 1342 | AU17: 44950.528 | AV17: 8 | AW17: 1374.625 | AX17: 1382
B18: 44958 | C18: 68 | D18: 58 | E18: 126 | F18: 66 | G18: 1261.8695 | H18: 1366 | L18: 1 | M18: 1212.7838 | N18: 1217 | R18: 1 | S18: 1227.3448 | T18: 1234 | U18: 56 | V18: 1396.6887 | W18: 1541 | X18: 1 | Y18: 1404.2812 | Z18: 1423 | AA18: 1 | AB18: 1379.8947 | AC18: 1390 | AJ18: 122 | AK18: 1 | AL18: 2 | AN18: 1 | AO18: 44958.501 | AP18: 1541 | AQ18: 44965.563 | AR18: 232 | AS18: 1227.3448 | AT18: 1234 | AU18: 44967.527 | AV18: 76 | AW18: 1379.8947 | AX18: 1390
B19: 44986 | C19: 185 | D19: 70 | E19: 255 | F19: 177 | G19: 1258.8363 | H19: 1366 | I19: 4 | J19: 1183.7711 | K19: 1366 | L19: 3 | M19: 1235.0567 | N19: 1359 | O19: 1 | P19: 1339.3468 | Q19: 1365 | U19: 65 | V19: 1394.8059 | W19: 1519 | X19: 4 | Y19: 1397.86 | Z19: 1456 | AA19: 1 | AB19: 1422.2817 | AC19: 1444 | AJ19: 242 | AK19: 8 | AL19: 4 | AM19: 1 | AO19: 45010.505 | AP19: 1519 | AQ19: 45010.434 | AR19: 124 | AS19: 1339.3468 | AT19: 1365 | AU19: 45007.512 | AV19: 71 | AW19: 1422.2817 | AX19: 1444
B25: Mês/ano | C25: Ocorrências | E25: Mês/ano | F25: 1000 ≥ Ig < 1300 W/m² | G25: Ig > 1367 W/m² | I25: Mês/ano | J25: < 30 seg | K25: < 1 min | L25: < 2 minutos | M25: < 3 minutos | N25: ≥ 3 minutos | P25: =I25 -> Mês/ano | Q25: < 30 seg | R25: < 1 min | S25: < 2 minutos | T25: < 3 minutos | U25: ≥ 3 minutos | W25: =P25 -> Mês/ano | X25: < 30 seg | Y25: < 1 min | Z25: < 2 minutos | AA25: < 3 minutos | AB25: ≥ 3 minutos | AD25: Dia/mês | AE25: Evento de maior magnitude [W/m²] | AF25: ="" | AG25: Dia/mês | AH25: Maior duração >1000 e <1367 [W/m²] | AI25: Maior duração >1367 [W/m²] | AJ25: ="" | AL25: Mês/ano | AM25: < 30 seg | AN25: < 1 min | AO25: < 2 minutos | AP25: < 3 minutos | AQ25: ≥ 3 minutos
B26: =B3 -> 44501 | C26: =E3 | E26: =B26 -> 44501 | F26: =C3/E3 -> #DIV/0! | G26: =D3/E3 -> #DIV/0! | I26: =E26 -> 44501 | J26: =AJ3/$E3 -> #DIV/0! | K26: =AK3/$E3 -> #DIV/0! | L26: =AL3/$E3 -> #DIV/0! | M26: =AM3/$E3 -> #DIV/0! | N26: =AN3/$E3 -> #DIV/0! | P26: =I26 -> 44501 | Q26: =G3 | R26: =J3 | S26: =M3 | T26: =P3 | U26: =S3 | W26: =P26 -> 44501 | X26: =V3 | Y26: =Y3 | Z26: =AB3 | AA26: =AE3 | AB26: =AH3 | AD26: =W26 -> 44501 | AE26: =AP3 | AG26: =W26 -> 44501 | AH26: =AR3 | AI26: =AV3 | AL26: =AG26 -> 44501 | AM26: =AJ3/$E3 -> #DIV/0! | AN26: =AK3/$E3 -> #DIV/0! | AO26: =AL3/$E3 -> #DIV/0! | AP26: =AM3/$E3 -> #DIV/0! | AQ26: =AN3/$E3 -> #DIV/0!
B27: =B4 -> 44531 | C27: =E4 | E27: =B27 -> 44531 | F27: =C4/E4 -> #DIV/0! | G27: =D4/E4 -> #DIV/0! | I27: =E27 -> 44531 | J27: =AJ4/$E4 -> #DIV/0! | K27: =AK4/$E4 -> #DIV/0! | L27: =AL4/$E4 -> #DIV/0! | M27: =AM4/$E4 -> #DIV/0! | N27: =AN4/$E4 -> #DIV/0! | P27: =I27 -> 44531 | Q27: =G4 | R27: =J4 | S27: =M4 | T27: =P4 | U27: =S4 | W27: =P27 -> 44531 | X27: =V4 | Y27: =Y4 | Z27: =AB4 | AA27: =AE4 | AB27: =AH4 | AD27: =AO4 | AE27: =AP4 | AG27: =W27 -> 44531 | AH27: =AR4 | AI27: =AV4 | AL27: =AG27 -> 44531 | AM27: =AJ4/$E4 -> #DIV/0! | AN27: =AK4/$E4 -> #DIV/0! | AO27: =AL4/$E4 -> #DIV/0! | AP27: =AM4/$E4 -> #DIV/0! | AQ27: =AN4/$E4 -> #DIV/0!
B28: =B5 -> 44562 | C28: =E5 | E28: =B28 -> 44562 | F28: =C5/E5 -> #DIV/0! | G28: =D5/E5 -> #DIV/0! | I28: =E28 -> 44562 | J28: =AJ5/$E5 -> #DIV/0! | K28: =AK5/$E5 -> #DIV/0! | L28: =AL5/$E5 -> #DIV/0! | M28: =AM5/$E5 -> #DIV/0! | N28: =AN5/$E5 -> #DIV/0! | P28: =I28 -> 44562 | Q28: =G5 | R28: =J5 | S28: =M5 | T28: =P5 | U28: =S5 | W28: =P28 -> 44562 | X28: =V5 | Y28: =Y5 | Z28: =AB5 | AA28: =AE5 | AB28: =AH5 | AD28: =AO5 | AE28: =AP5 | AG28: =W28 -> 44562 | AH28: =AR5 | AI28: =AV5 | AL28: =AG28 -> 44562 | AM28: =AJ5/$E5 -> #DIV/0! | AN28: =AK5/$E5 -> #DIV/0! | AO28: =AL5/$E5 -> #DIV/0! | AP28: =AM5/$E5 -> #DIV/0! | AQ28: =AN5/$E5 -> #DIV/0!
B29: =B6 -> 44593 | C29: =E6 | E29: =B29 -> 44593 | F29: =C6/E6 -> #DIV/0! | G29: =D6/E6 -> #DIV/0! | I29: =E29 -> 44593 | J29: =AJ6/$E6 -> #DIV/0! | K29: =AK6/$E6 -> #DIV/0! | L29: =AL6/$E6 -> #DIV/0! | M29: =AM6/$E6 -> #DIV/0! | N29: =AN6/$E6 -> #DIV/0! | P29: =I29 -> 44593 | Q29: =G6 | R29: =J6 | S29: =M6 | T29: =P6 | U29: =S6 | W29: =P29 -> 44593 | X29: =V6 | Y29: =Y6 | Z29: =AB6 | AA29: =AE6 | AB29: =AH6 | AD29: =AO6 | AE29: =AP6 | AG29: =W29 -> 44593 | AH29: =AR6 | AI29: =AV6 | AL29: =AG29 -> 44593 | AM29: =AJ6/$E6 -> #DIV/0! | AN29: =AK6/$E6 -> #DIV/0! | AO29: =AL6/$E6 -> #DIV/0! | AP29: =AM6/$E6 -> #DIV/0! | AQ29: =AN6/$E6 -> #DIV/0!
B30: =B7 -> 44621 | C30: =E7 -> 295 | E30: =B30 -> 44621 | F30: =C7/E7 -> 0.65423729 | G30: =D7/E7 -> 0.34576271 | I30: =E30 -> 44621 | J30: =AJ7/$E7 -> 0.9559322 | K30: =AK7/$E7 -> 0.033898305 | L30: =AL7/$E7 -> 0.010169492 | M30: =AM7/$E7 -> 0 | N30: =AN7/$E7 -> 0 | P30: =I30 -> 44621 | Q30: =G7 -> 1268.8487 | R30: =J7 -> 1221.6485 | S30: =M7 -> 1327.7582 | T30: =P7 | U30: =S7 | W30: =P30 -> 44621 | X30: =V7 -> 1391.9232 | Y30: =Y7 -> 1412.6719 | Z30: =AB7 -> 1442.4992 | AA30: =AE7 | AB30: =AH7 | AD30: =AO7 -> 44645.457 | AE30: =AP7 -> 1528 | AG30: =W30 -> 44621 | AH30: =AR7 -> 91 | AI30: =AV7 -> 84 | AL30: =AG30 -> 44621 | AM30: =AJ7/$E7 -> 0.9559322 | AN30: =AK7/$E7 -> 0.033898305 | AO30: =AL7/$E7 -> 0.010169492 | AP30: =AM7/$E7 -> 0 | AQ30: =AN7/$E7 -> 0
B31: =B8 -> 44652 | C31: =E8 -> 466 | E31: =B31 -> 44652 | F31: =C8/E8 -> 0.84549356 | G31: =D8/E8 -> 0.15450644 | I31: =E31 -> 44652 | J31: =AJ8/$E8 -> 0.95922747 | K31: =AK8/$E8 -> 0.030042918 | L31: =AL8/$E8 -> 0.008583691 | M31: =AM8/$E8 -> 0.0021459227 | N31: =AN8/$E8 -> 0 | P31: =I31 -> 44652 | Q31: =G8 -> 1239.2594 | R31: =J8 -> 1279.9811 | S31: =M8 -> 1106.5945 | T31: =P8 | U31: =S8 | W31: =P31 -> 44652 | X31: =V8 -> 1394.0556 | Y31: =Y8 -> 1399.8409 | Z31: =AB8 -> 1410.9899 | AA31: =AE8 -> 1419.5954 | AB31: =AH8 | AD31: =AO8 -> 44677.455 | AE31: =AP8 -> 1490 | AG31: =W31 -> 44652 | AH31: =AR8 -> 81 | AI31: =AV8 -> 131 | AL31: =AG31 -> 44652 | AM31: =AJ8/$E8 -> 0.95922747 | AN31: =AK8/$E8 -> 0.030042918 | AO31: =AL8/$E8 -> 0.008583691 | AP31: =AM8/$E8 -> 0.0021459227 | AQ31: =AN8/$E8 -> 0
B32: =B9 -> 44682 | C32: =E9 -> 405 | E32: =B32 -> 44682 | F32: =C9/E9 -> 0.99753086 | G32: =D9/E9 -> 0.0024691358 | I32: =E32 -> 44682 | J32: =AJ9/$E9 -> 0.95555556 | K32: =AK9/$E9 -> 0.037037037 | L32: =AL9/$E9 -> 0.0049382716 | M32: =AM9/$E9 -> 0.0024691358 | N32: =AN9/$E9 -> 0 | P32: =I32 -> 44682 | Q32: =G9 -> 1172.7135 | R32: =J9 -> 1172.7586 | S32: =M9 -> 1137.6488 | T32: =P9 -> 1178.8713 | U32: =S9 | W32: =P32 -> 44682 | X32: =V9 -> 1376 | Y32: =Y9 | Z32: =AB9 | AA32: =AE9 | AB32: =AH9 | AD32: =AO9 -> 44708.497 | AE32: =AP9 -> 1376 | AG32: =W32 -> 44682 | AH32: =AR9 -> 171 | AI32: =AV9 -> 1 | AL32: =AG32 -> 44682 | AM32: =AJ9/$E9 -> 0.95555556 | AN32: =AK9/$E9 -> 0.037037037 | AO32: =AL9/$E9 -> 0.0049382716 | AP32: =AM9/$E9 -> 0.0024691358 | AQ32: =AN9/$E9 -> 0
